Workbook

Sheet Exercices
B1: Elément | C1: Niv1 | D1: Niv2 | E1: Niv3 | F1: Niv4 | G1: Phases
A3: 1.1 | B3: Sol | C3: Vérif/Ctrl | D3: Voile | E3: ------------------ | F3: ------------------
A4: 1.2 | B4: Sol | C4: Vérif/Ctrl | D4: Sellette | E4: ------------------ | F4: ------------------
A5: 1.3 | B5: Sol | C5: Vérif/Ctrl | D5: Secours | E5: ------------------ | F5: ------------------
A6: 1.4 | B6: Sol | C6: Gonflage | D6: Sans vent | E6: Pente école | F6: Dos Voile
A7: 1.5 | B7: Sol | C7: Gonflage | D7: Sans vent | E7: Pente école | F7: Face voile
A8: 1.6 | B8: Sol | C8: Gonflage | D8: Avec vent | E8: Terrain plat | F8: Face voile
A11: 2.1 | B11: Air | C11: Pilotage | D11: Tangage | E11: Non accel. | G11: Ressource/Abattée/Accélération
A12: 2.2 | B12: Air | C12: Pilotage | D12: Wings over | E12: Non accel.
A13: 2.3 | B13: Air | C13: Pilotage | D13: Oreille 1 suspente | E13: Non accel. | G13: Avec maintien du cap
A14: 2.4 | B14: Air | C14: Pilotage | D14: Oreille 1 suspente | E14: Accéléré | G14: Avec maintien du cap
A15: 2.5 | B15: Air | C15: Pilotage | D15: Oreille 2 suspentes | E15: Non accel. | G15: Avec maintien du cap
A16: 2.6 | B16: Air | C16: Pilotage | D16: Oreille 2 suspentes | E16: Accéléré | G16: Avec maintien du cap
A17: 2.7 | B17: Air | C17: Pilotage | D17: Oreille élévateur | E17: Non accel. | G17: Avec maintien du cap
A18: 3.1 | B18: Air | C18: Incidents | D18: Ferm Asy 1 suspente | E18: Non accel.
A19: 3.11 | B19: Air | C19: Incidents | D19: Ferm Asy 1 suspente | E19: Accéléré 1er barr.
A20: 3.12 | B20: Air | C20: Incidents | D20: Ferm Asy 1 suspente | E20: Accéléré 2ième barr.
A21: 3.13 | B21: Air | C21: Incidents | D21: Ferm Asy 2 suspentes | E21: Non accel.
A22: 3.14 | B22: Air | C22: Incidents | D22: Ferm Asy 2 suspentes | E22: Accéléré 1er barr.
A23: 3.15 | B23: Air | C23: Incidents | D23: Ferm Asy 2 suspentes | E23: Accéléré 2ième barr.
A24: 3.16 | B24: Air | C24: Incidents | D24: Ferm Asy élévateur | E24: Non accel.
A25: 3.17 | B25: Air | C25: Incidents | D25: Ferm Asy élévateur | E25: Accéléré 1er barr.
A26: 3.18 | B26: Air | C26: Incidents | D26: Ferm Asy élévateur | E26: Accéléré 2ième barr.
A27: 3.19 | B27: Air | C27: Incidents | D27: Frontale | E27: Non accel.
A28: 3.2 | B28: Air | C28: Incidents | D28: Frontale | E28: Accéléré 1er barr.
A29: 3.21 | B29: Air | C29: Incidents | D29: Frontale | E29: Accéléré 2ième barr.
A30: 3.22 | B30: Air | C30: Incidents | D30: Décrochage | E30: ------------------
A33: 4.1 | B33: Air | C33: Descente | D33: 360°
A34: 4.1 | B34: Air | C34: Descente | D34: B
B39: Documentation
B40: Dossier PP 161, 162, 163
B41: Manuel voile Golden
B42: Internet
B43: Stage

Sheet Comparatif voile
A1: Marque | B1: Modèle | C1: Année | D1: Taille | F1: PTV | G1: Class. | H1: Surf. à plat | I1: CH. Alaire à plat | J1: Surf. Proj. | K1: CH. Alaire proj | L1: Aplat. | M1: Allongement | N1: Allongement projeté | O1: Poids | P1: Nbre cellule | Q1: Nbre lignes | R1: Longueur cône | S1: Mettrage suspente | T1: prix | U1: Rmqs | V1: Essai
A2: Air Cross | B2: U Cruise | C2: 2016 | D2: M | E2: =CONCATENATE(A2, " - ",B2," - ",D2) -> Air Cross - U Cruise - M | F2: 75 / 100 | G2: B | H2: 26.67 | I2: =Matériel!$G$14/H2 -> #VALUE! | J2: 22.86 | K2: =Matériel!$G$14/J2 -> #VALUE! | L2: =(H2-J2)/H2*100 -> 14.285714 | M2: 5.6 | N2: 4.19 | O2: 5.8 | P2: 65 | Q2: 3 / 4 / 3 | R2: 7.58 | T2: 3900
A3: Mac Para | B3: Elan | C3: 2014 | D3: 26 | E3: =CONCATENATE(A3, " - ",B3," - ",D3) -> Mac Para - Elan - 26 | F3: 80 / 100 | G3: C | H3: 26.1 | I3: =Matériel!$G$14/H3 -> #VALUE! | M3: 6.2 | N3: 4.52 | O3: 5.7 | P3: 63 | Q3: 2+1 / 4 / 3 | R3: 6.77 | S3: 252 | T3: 3500 | U3: V light 4,5kg
A4: NOVA | B4: Mentor 4 | C4: 2015 | D4: S | E4: =CONCATENATE(A4, " - ",B4," - ",D4) -> NOVA - Mentor 4 - S | F4: 80 / 100 | G4: B | H4: 26 | I4: =Matériel!$G$14/H4 -> #VALUE! | M4: 5.43 | O4: 5.3 | P4: 55 | Q4: 2+1 / 4 / 3 | R4: 6.87 | S4: 237 | T4: 3800 | U4: V light 3,75 kg
A5: Ozone | B5: Delta | C5: 2010 | D5: M | E5: =CONCATENATE(A5, " - ",B5," - ",D5) -> Ozone - Delta - M | F5: 80/100 | G5: C | H5: 26 | I5: =Matériel!$G$14/H5 -> #VALUE! | J5: 22.4 | K5: =Matériel!$G$14/J5 -> #VALUE! | L5: =(H5-J5)/H5*100 -> 13.846154 | M5: 5.85 | N5: 4.4 | O5: 5.6 | P5: 58 | Q5: 3 / 3 / 4 | R5: 7.59 | S5: 308 | T5: 3650 | V5: Essai Ozone Delta 1 de Claire, En C, taille M (PTV 80 -100) du coup avec mon PTV de 91 kg, ça fait une charge alaire de 3,46 kg/m², Allongement à plat 5,8 / Poids 5,6 kg, Avant le vol, j'ai trouvé les branches des élévateurs difficile à manier, car trop fins par rapport à ceux de la Golden, d'ailleur je décolle avec les freins qui passent entre les A et B. Face voile, ça gonfle bien,peut-être un peu lentement. Je retrouve les sensations de la Jedi2, tout en douceur, des commandes assez légères, comme quoi mon à priori des commandes ozones physique était eronné. En terme de prise de commande, d'effort physique et de retour d'info, c'est la meilleur que j'ai essayé jusqu'à maintenant. Le virage est moins bon que celui des autres voiles essayées, plus proche de celui de la Golden, avec une tendance à engager de l'extèrieur, à piloter avec la commande ext. Elle semble très stable en tangage, elle donne les infos qui vont bien en roulis. Elle m'a semblé un peu lente, j'ai pplus suvent vu sur le GPS des vitesses entre 33 et 35 qu'au dessus. Je pense que du fait de la faible charge alaire ... et peut-être aussi des 350 heures de vol de la voile, elle manque de réactivité, de vivacité, de vitesse. Et comme avec la Diamir2, je trouve ces voiles classées EN C, bien facile à piloter, plus que ma Golden4 en tout cas et tr-s rassurante, plus que l'Apolo par exemple. Je vais demander à Thierry de me préter sa delta 2 pour voir ....
A6: Mac Para | B6: Elan 2 | C6: 2017 | D6: 26 | E6: =CONCATENATE(A6, " - ",B6," - ",D6) -> Mac Para - Elan 2 - 26 | F6: 80 / 100 | G6: C | H6: 25.8 | I6: =Matériel!$G$14/H6 -> #VALUE! | J6: 21.9 | K6: =Matériel!$G$14/J6 -> #VALUE! | L6: =(H6-J6)/H6*100 -> 15.116279 | M6: 6.27 | N6: 4.72 | O6: 4.9 | P6: 63 | Q6: 2+1 / 4 / 3 | R6: 7.39
A7: Mac Para | B7: Eden 6 | C7: 2016 | D7: 26 | E7: =CONCATENATE(A7, " - ",B7," - ",D7) -> Mac Para - Eden 6 - 26 | F7: 78 / 100 | G7: B | H7: 25.6 | I7: =Matériel!$G$14/H7 -> #VALUE! | J7: 21.95 | K7: =Matériel!$G$14/J7 -> #VALUE! | L7: =(H7-J7)/H7*100 -> 14.257813 | M7: 5.91 | N7: 4.41 | O7: 5.2 | P7: 56 | Q7: 2+1 / 4 / 3 | R7: 7.13 | S7: 238 | T7: 3400 | U7: V light 4,3kg
A8: Triple seven | B8: Queen | C8: 2013 | D8: M | E8: =CONCATENATE(A8, " - ",B8," - ",D8) -> Triple seven - Queen - M | F8: 80 / 100 | G8: C | H8: 25.5 | I8: =Matériel!$G$14/H8 -> #VALUE! | J8: 21.4 | K8: =Matériel!$G$14/J8 -> #VALUE! | L8: =(H8-J8)/H8*100 -> 16.078431 | M8: 6.2 | N8: 4.64 | O8: 5 | P8: 62 | Q8: 1+1 / 3 /2 | T8: 3700
A9: Gradient | B9: Aspen 5 | C9: 2014 | D9: 26 | E9: =CONCATENATE(A9, " - ",B9," - ",D9) -> Gradient - Aspen 5 - 26 | F9: 85 / 103 | G9: C | H9: 25.5 | I9: =Matériel!$G$14/H9 -> #VALUE! | J9: 21.49 | K9: =Matériel!$G$14/J9 -> #VALUE! | L9: =(H9-J9)/H9*100 -> 15.72549 | M9: 6.25 | N9: 4.54 | O9: 5.1 | P9: 64 | Q9: 2 / 3 / 2 | R9: 7.3 | S9: 233 | T9: 3750
A10: Advance | B10: Sigma 9 | C10: 2014 | D10: 25 | E10: =CONCATENATE(A10, " - ",B10," - ",D10) -> Advance - Sigma 9 - 25 | F10: 75 / 100 | G10: C | H10: 25.1 | I10: =Matériel!$G$14/H10 -> #VALUE! | J10: 20.9 | K10: =Matériel!$G$14/J10 -> #VALUE! | L10: =(H10-J10)/H10*100 -> 16.733068 | M10: 5.85 | N10: 4.1 | O10: 4.9 | P10: 59 | Q10: 2+1 / 3 / 4 | R10: 7.5 | T10: 3800
A11: ITV | B11: Jedi 2 | C11: 2015 | D11: M | E11: =CONCATENATE(A11, " - ",B11," - ",D11) -> ITV - Jedi 2 - M | F11: 80 / 100 | G11: B | H11: 25 | I11: =Matériel!$G$14/H11 -> #VALUE! | J11: NC | M11: 5.7 | N11: NC | O11: 4.5 | P11: 55 | Q11: 2 / 3 / 2 | R11: 6.53 | T11: 3350 | V11: Essai ITV JEDI 2, En B, taille L (PTV 95 -120) du coup avec mon PTV de 91 kg, ça fait une charge alaire de 3,27 kg/m², Allongement à plat 5,7 / Allongement projeté 4,5 / Longueur cône suspentage 6,5m / Metrage suspentes ? m / 55 cellules / Suspentage en 2 / 3 / 2. Poids 4,5 kg, Toutes les caractéristiques techniques sont pour moi au vert, sauf le PTV suite erreur de l'importateur à qui nous avions demandé une M. Je ne m'en rendrais compte qu'une fois posé au moment de plier avec l'aide de Pierre ou on s'est dit qu'elle ressemblé à un Bi place... Avant le vol, j'ai trouvé les élévateurs un peu compliqué avec 2 "A" à 1 suspente, je suppose pour les oreilles. Mais après quelques "noeuds" je finis par m'en sortir. Les suspentes sont gainés jusqu'en haut, on se demande pourquoi, habituellement seules les basses sont gainées. Ca gonfle très bien, très facilement. Alors que je ne savais pas que C T une L, je me souvien bien m'eêtre dit qu'elle étais très douce, trés veloutée. Je me suis aussi dit qu'lle n'avançait pas beaucoup mais que les conditions du jour ne permettais pas de certutitude, avec du N et une bonne tendeuse orageuse sur la chaine qui se confirmera. En fait je me suis régalé, une véritable monde de douceur. En plus un vautour m'a montré la voie du coté du Col de Larrieu, je l'ai vivement remercié en vol, suis pas sur qu'il est vraiment compris ma gratitude ... que du plaisir. Au retour d'Herbes blanche, le ciel devenat menaçant, j'ai forcé l'allure, accéléré o fond, certs ça n'allait pas très vite, mais encore une fois, le ciel était bien noir derrière moi. Du cou, j'en ai profité pour essayer oreilles + acc., elles flappent ppas mal, mais c'est tenable, contrairement à la Diamir 2. Arrivé haut au dessu sd'Arbas, j'ai envoyé de bon 350 ... enfin à mo niveau, waouh la sortie, comment dit on "aérienne". Mais en tout instant du vol, elle m'a donné confiance, aucune fermeture, RAS sur toute la ligne. Si Thierry se debourille avec ITV, j'essaireai bien la M (PTV 80-100), je suis à 91. Mais je crains que les commandes deviennnet trop physique, là avec la L c'était limite pour moi. A suivre avec une M ???
A12: Swing | B12: Nyos | C12: 2015 | D12: M | E12: =CONCATENATE(A12, " - ",B12," - ",D12) -> Swing - Nyos - M | F12: 80 / 100 | G12: B | H12: 25 | I12: =Matériel!$G$14/H12 -> #VALUE! | J12: 21.6 | K12: =Matériel!$G$14/J12 -> #VALUE! | L12: =(H12-J12)/H12*100 -> 13.6 | M12: 5.8 | N12: 4.4 | O12: 5 | P12: 59 | Q12: 2+1 / 3 / 4 | R12: 6.74 | T12: 3900
A13: UP | B13: Kibo | C13: 2016 | D13: SM | E13: =CONCATENATE(A13, " - ",B13," - ",D13) -> UP - Kibo - SM | F13: 75 / 95 | G13: B | H13: 24.9 | I13: =Matériel!$G$14/H13 -> #VALUE! | M13: 5.7 | O13: 4.7 | P13: 49 | Q13: 2+1 / 4 / 3 | R13: 6.75 | S13: 268 | T13: 3600
A14: U-Turn | B14: Blacklight 2 | C14: 2016 | D14: S | E14: =CONCATENATE(A14, " - ",B14," - ",D14) -> U-Turn - Blacklight 2 - S | F14: 65 / 90 | G14: B | H14: 24.8 | I14: =Matériel!$G$14/H14 -> #VALUE! | J14: 21.55 | K14: =Matériel!$G$14/J14 -> #VALUE! | L14: =(H14-J14)/H14*100 -> 13.104839 | M14: 5.61 | N14: 4.24 | O14: 4.7 | P14: 59 | Q14: 2+1 / 4 / 3 | R14: 7.2 | S14: 239
A15: Sky Paragliders | B15: Antéa 2 | C15: 2011 | D15: M | E15: =CONCATENATE(A15, " - ",B15," - ",D15) -> Sky Paragliders - Antéa 2 - M | F15: 75 / 95 | G15: C | H15: 24.6 | I15: =Matériel!$G$14/H15 -> #VALUE! | J15: 21.83 | K15: =Matériel!$G$14/J15 -> #VALUE! | L15: =(H15-J15)/H15*100 -> 11.260163 | M15: 5.5 | N15: 4.24 | O15: 4.9 | P15: 59 | Q15: 3 / 4 / 3 / 2 | T15: 3450
A16: Niviuk | B16: Ikuma | C16: 2015 | D16: 25 | E16: =CONCATENATE(A16, " - ",B16," - ",D16) -> Niviuk - Ikuma - 25 | F16: 80 / 100 | G16: B | H16: 24.5 | I16: =Matériel!$G$14/H16 -> #VALUE! | J16: 20.75 | K16: =Matériel!$G$14/J16 -> #VALUE! | L16: =(H16-J16)/H16*100 -> 15.306122 | M16: 5.7 | N16: 4.26 | O16: 4.9 | P16: 57 | Q16: 2 / 2 / 3 | R16: 7.2 | S16: 238 | T16: 3800
A17: Sky Paragliders | B17: Apollo | C17: 2015 | D17: M | E17: =CONCATENATE(A17, " - ",B17," - ",D17) -> Sky Paragliders - Apollo - M | F17: 74 / 94 | G17: B | H17: 24.5 | I17: =Matériel!$G$14/H17 -> #VALUE! | J17: 21.56 | K17: =Matériel!$G$14/J17 -> #VALUE! | L17: =(H17-J17)/H17*100 -> 12 | M17: 5.45 | N17: 4.2 | O17: 4.6 | P17: 55 | Q17: 2+1 / 4 / 3 | R17: 6.94 | T17: 3750 | V17: Essai Sky paragliders Apolo, En B, taille M (PTV 74-94), Allongement à plat 5,5 / Allongement projeté 4,2 / Longueur cône suspentage 6,9m / Metrage suspentes ? m / 55 cellules / Suspentage en 2+1 / 4 / 3. Poids 4,6 kg, Toutes les caractéristiques techniques sont pour moi au vert. Le 09/05, essai en // avec Thierry qui vole sous la Diamir2. Un premier très bon point, le poids, 4,4 kg, c'est 300g de moins que ma Golden et pareil que la Diamir2. Elle est livrée avec un sac chaussette, c'est la première fois que j'en utilise un, c'est vrai que c'est bien cool à utiliser. 1er contact ok avec la voile, suspentes basses gainées, les élévateurs sont quand même bien fins… dommage qui ne s'élargisse pas au niveau des maillons. Les poignées de freins sont accrochées par une pression, la prise en mains des commandes ne pose pas de problème. Il s'agit de poignée souple, mais avec un gadget qui va s'avéré interressant en vol, une petite palette rigide basculante qui se cale entre pouce et index et qui donne une prise de commande précise. Par contre ça fait plus travailler les mains, d'ou fatigue, mais rien n'empêche alors de reprendre la position dragonne. Coté suspentage, le démélage est fluide et simple. Déco face voile trés facile, très léger, presque aérien. Je me permets même de temporiser la voile au dessus de ma tête après m'être retourné, du caviar... quoique je n'en ai jamais gouté... En sortie de déco, grosse surprise, j'ai l'impression d'avoir un gun au dessus de la tête quoique je n'en ai jamais piloté non plus, mais elle réagit très vite, elle est d'une légèreté aux commandes que je n'avais pas rencontré sur les voiles essayées précédemment. Beaucoup de mvts de roulis retransmis à la sellette. Tout le début du vol a été assez perturbé à cause de ça. Puis peu à peu, je ne le ai plus senti comme une gène, au profit d'une qualité de virage et d'une précision de commandes assez génial. Aucune fermeture à signaler pendant les 1h40 de vol. C'est bien la conception de la voile qui donne des bouts d'ailes sensibles qui donnent bcp d'infos (peut-être trop...) mais qui permettent certainement la qualité de virage et la "délicatesse" des commandes. Avec du recul ça me rappelle les commandes de mon Aspen 1er du nom. En thermique, j'ai fait aussi bien que Thierry ou qu'une delta 2 ou que Tim avec sa Mantra, et comme ils sont tous bien meilleur pilote que moi, c'est que l'aile est facile. En transistion, on a fait 3/4 bonne longueur de comparaison, la Diamir2 est mieux, il me semble en particulier dés qu'il faut un chouilla de vitesse en plus en début d'accélérateur ou quand c'est un peu turbulent... le fameux "floating" ? Coté accélérateur, c'est très, très doux également, la course est plutot faible, en tout cas plus que sur ma Gilden ou que la Diamir. Il me semble que dés qu'on accélere, la finess se dégrade, je pense que cest moins bon que la Diamir2. Mais il faut bien que 0,6 points de finesse fassent la différence quelque part. Pour l'instant à choisir je resterai sur la Diamir2, un peu pour les perfs mais surtouts par la gestion globale plus facile en vol, je suis sûr que sur plusieurs heures de vols, la Diamir2 est moins exigeante.
A18: Advance | B18: Sigma 10 | C18: 2017 | D18: 25 | E18: =CONCATENATE(A18, " - ",B18," - ",D18) -> Advance - Sigma 10 - 25 | F18: 80 / 100 | G18: C | H18: 24.5 | I18: =Matériel!$G$14/H18 -> #VALUE! | J18: 20.96 | K18: =Matériel!$G$14/J18 -> #VALUE! | L18: =(H18-J18)/H18*100 -> 14.44898 | M18: 6.16 | N18: 4.6 | O18: 4.9 | P18: 66 | Q18: 2+1 / 4 / 3 | R18: 7.46 | T18: 4250
A19: Niviuk | B19: Artik 4 | C19: 2014 | D19: 25 | E19: =CONCATENATE(A19, " - ",B19," - ",D19) -> Niviuk - Artik 4 - 25 | F19: 75 / 95 | G19: C | H19: 24.5 | I19: =Matériel!$G$14/H19 -> #VALUE! | M19: 6.1 | N19: 4.56 | O19: 5.2 | P19: 63 | Q19: 1+1 / 2 / 3 | R19: 7.5 | S19: 245 | T19: 3800 | U19: V light 4kg
A20: Gradient | B20: Golden 4 | C20: 2013 | D20: 24 | E20: =CONCATENATE(A20, " - ",B20," - ",D20) -> Gradient - Golden 4 - 24 | F20: 75 / 90 | G20: B | H20: 24.4 | I20: =Matériel!$G$14/H20 -> #VALUE! | J20: 21.02 | K20: =Matériel!$G$14/J20 -> #VALUE! | L20: =(H20-J20)/H20*100 -> 13.852459 | M20: 5.3 | N20: 4.16 | O20: 4.9 | P20: 51 | Q20: 2+1 / 4 / 3 | R20: 6.57 | S20: 241 | T20: 3340
A21: Ozone | B21: Delta 2 | C21: 2013 | D21: MS | E21: =CONCATENATE(A21, " - ",B21," - ",D21) -> Ozone - Delta 2 - MS | F21: 75 / 95 | G21: C | H21: 24.4 | I21: =Matériel!$G$14/H21 -> #VALUE! | J21: 20.5 | K21: =Matériel!$G$14/J21 -> #VALUE! | L21: =(H21-J21)/H21*100 -> 15.983607 | M21: 6 | N21: 4.4 | O21: 5 | P21: 62 | Q21: 2+1 / 3 / 4 | T21: 3800 | V21: Essai Ozone Delta 2 En C, taille S (PTV 65-85), Charge alaire 3,9kg/m² à plat et 4,6 projeté. Allongement à plat 6 / Allongement projeté 4,4 / 62 cellules / Suspentage en 2+1 / 3 / 4. Poids 4,7 kg. La voile est celle de Thierry Damian, elle a 450 heures de vols, je ne sais évidemment pas comment elle était neuve, mais franchement, à part son état ext., impossible de détecter son "âge". Déco impossible à juger, j'ai décoler face voile et twister, trés nul. Je n'ai jamais eu l'impression d'être au dessus du PTV (+5kg), la voile est douce, réagit aux commandes sur 20 à 30 cms sans beaucoup d'effort, du même niveau que la Diamir 2, je suppose qu'en apprenant la voile, elle est très très bien en thermique. Pas de mouvement de lacet, pas d'engagement du coté ext. comme avec la Golden ou l'Apolo. Par contre moins d'informatrions pertinentes pour centrer le thermique. En transition y'a pas photo, ça plane, peut-être mieux que la Diamir 2, mais par contre elle tangue régulièrement, j'ai cru que CT de ma faute, mais Thierry me l'a ensuite confirmé, alors que la Diamir2 est extrèmement stable. Sur essai d'oreille asymétrique, elle part nettement du coté ... ouvert, comme la Golden, comme quoi y'a vraiment un truc étarnge, ou alors c'est moi qui contre involontairement. J'ai essayé qque tangages, elle a comportement étonnant, dans l'abatée, elle semble faire une pause quand elle passe à la vertivale, puis repartir vers l'avant. Mais le tangage est équivalent à la Golden, peut-être plus dynamique que la Diamir2. Par contre elle semble vive en roulis, faudrait ré essayer. Du coup, la Diamir 2 reste m'a favorite, il faudrait essayer une delta 3, mais elle est encore plus chère que la Diamir ... alors...
A22: Sky Paragliders | B22: Argos | C22: 2014 | D22: M | E22: =CONCATENATE(A22, " - ",B22," - ",D22) -> Sky Paragliders - Argos - M | F22: 75 / 90 | G22: C | H22: 24.15 | I22: =Matériel!$G$14/H22 -> #VALUE! | M22: 5.5 | O22: 4.4 | P22: 59 | Q22: 3 / 4 / 3 | R22: 7.11
A23: Air Design | B23: Rise 2 | C23: 2014 | D23: S | E23: =CONCATENATE(A23, " - ",B23," - ",D23) -> Air Design - Rise 2 - S | F23: 70 / 90 | G23: B | H23: 24 | I23: =Matériel!$G$14/H23 -> #VALUE! | M23: 5.65 | O23: 5.2 | P23: 49 | Q23: 2+1 / 3 / 3 | S23: 252 | T23: 3500 | U23: V light 3,9kg
A24: Nervures | B24: Diamir 2 | C24: 2016 | D24: S | E24: =CONCATENATE(A24, " - ",B24," - ",D24) -> Nervures - Diamir 2 - S | F24: 70 / 90 | G24: C | H24: 24 | I24: =Matériel!$G$14/H24 -> #VALUE! | J24: 20.6 | K24: =Matériel!$G$14/J24 -> #VALUE! | L24: =(H24-J24)/H24*100 -> 14.166667 | M24: 6.1 | N24: 4.74 | O24: 4.5 | P24: 63 | Q24: 2+1 / 4 / 3 | R24: 6.93 | S24: 291 | T24: 4150 | U24: V light 3,7kg | V24: Essai Nervures Diamir 2, En C, taille S (PTV 70-90), Allongement à plat 6,1 / Allongement projeté 4,74 / Longueur cône suspentage 6,9 m / Metrage suspentes 271 m / 63 cellules / Suspentage en 2+1 / 4 / 3. Poids 4,5 kg, Les caractéristiques techniques sont pour moi au vert, je suis étonné de la longueur totale de suspentes ... sauf le prix. Le 23/04, gros vol de 75 kms A/R Arbas-Sacon. Manquant terriblement de référence, je dirai que la voile est parfaite sauf les élévateurs/poignées de freins qui ne me conviennent pas du tout et les oreilles qui battent beaucoup et s'ouvrent difficilement. Le gonflage est facile, confirmé par Thierry Damian qui a bcp plus d'expérience que moi. On sent bien que ça plane et que ça avance, un peu mieux légèrement accéléré, et qu'elle est utilisable à fond d'accélérateur. L'effort aux commandes est plus élevé que sur la Golden, mais peut-être faudrait-il la laisser plus voler en thermique avec plus d'appui sellette ? Tjrs T Damian dit que c'est équivalent à la delta 2. Mais là j'avais la ventrale plutot serré, je sentais bien que je n'avais quasiment pas d'efficacité sellette. Peut-être aussi que je la charge trop ? L'utilisation de l'accélérateur est dans la limite haute pour l'effort demandé. Les + comme ça viteuf : La légèreté, les suspentes gainées en parties basses, l'utilisation de l'accélérateur, à priori la gestion des incidents, j'ai pris une grosse aymétrique accéléré à fond, j'ai à peine eu le temps de réagir en lachant l'accélérateur qu'elle avait fait un quart de tour coté fermé et qu'elle été déjà réouverte et quelques bouts d'ailes insignifiants. idem pour des dégonflages/regonflage instantannée du BA. Par contre elle est chère ! A réessayer après d'autres essais ? Et ben justement 2d essai le 18/07, avec 2 vols. Au premier grosse connerie de ma part au déco, je la laisse me dépasser et elle ferme, je suis à 2 doigts du crash. Du coup je passe la suite du vol à me calmer dans des petits thermique du coté de Bourrus. Elle troune bien, mais moins que l'Apolo ou la Nevada et ses commandes demandent plus d'effort, ça confirme bien mon 1er ressenti. En fait je suis presque sûr que c'est une machine à cross, facile, peu de mouvement parasites sauf peut-e^tre des petits coup de "raquettes" en roulis. Le 2d vols m'a juste servi à décoller sans vent, voir cul d'ailleur, en m'appliquant pour remonter mon moral. Chose faite. J'ai enchainé qques essais dont des petits wings en freinant des 2 cotés, je pense que je finirai par y arriver. Cette voile est vraiment super, mais j'achète la Nevada2, plus facile à piloter, moins physique et moins cher !!!
A25: Swing | B25: Nexus | C25: 2015 | D25: S | E25: =CONCATENATE(A25, " - ",B25," - ",D25) -> Swing - Nexus - S | F25: 74 / 98 | G25: C | H25: 24 | I25: =Matériel!$G$14/H25 -> #VALUE! | M25: 6.1 | N25: 4.7 | O25: 5.2 | P25: 64 | Q25: 2+1 / 3 / 4 | R25: 7.13
A26: Gradient | B26: Nevada 2 | C26: 2016 | D26: 24 | E26: =CONCATENATE(A26, " - ",B26," - ",D26) -> Gradient - Nevada 2 - 24 | F26: 75 / 90 | G26: B | H26: 23.2 | I26: =Matériel!$G$14/H26 -> #VALUE! | J26: 19.61 | K26: =Matériel!$G$14/J26 -> #VALUE! | L26: =(H26-J26)/H26*100 -> 15.474138 | M26: 5.75 | N26: 4.14 | O26: 4.7 | P26: 56 | Q26: 2 / 3 / 2 | R26: 7.07 | S26: 215 | T26: 3750 | U26: V light 3,8 kg, meme ^prix | V26: J'écris ce CR après achat, c'est donc encore un peu plus subjectif. 7 heures d'essai + 2 heures de gonflage. C'est l'une des moins ambitieuse des voiles que j'envisageai, du coup complètement dans mon cahier des charges, EN B, Allongement à plat 5,75 / Allongement projeté 4,14 / Longueur cône suspentage 7 m / Metrage suspentes 214 m / 56 cellules / Suspentage en 2 / 3 / 2. Poids 3,9 kg en light, ce sont donc des caractériqtiques très proche de la Golden, l'allongement projeté est même inférieure. Le supsentage est minimaliste, mais idéale en terme de gainage pour les parties basses. Elélvateurs très facile à manier, par contre les poignées sont trop raide en gants fins, il faudra que j'ajoute une poignée type pilotage. La longueur totale de suspentes des super étonnantes, certainement la plus basse dans cette catégorie. A noter la simplicité globale de la voile, des joncs très fins, ce qui fait que je la plie à l'ancienne, pas de prise de tête excessif. Le gonflage est délicat, si on ne l'a met pas sufisamment en corole, elle gonfle par les bouts d'aile. c'est du aux 2 suspentes reliées au même maillon d'élélvateur. Face voile, il vaut mieux prendre les 2 suspents centrales au dessus du maillon. Ensuite elle monte doucement et semble marquer un point d'arret 10/20° avant d'arriver en haut. Certainement des atouts par vent fort, je n'ai pas pu tester, mais une réelle attention par vent faible ou nul. Je l'ai quand même décoller par très léger vent de cul au PLanot, et tout c'est bien passé. En vol, 2 caractéristiques majeurs : La 1ere, elle va vite, au feeling la plus rapide de toutes celle essayé, et accéléré c'est encore plus impressionnant. J'ai lu au GPS des vitesses que je n'avais jamais vu en air calme. La 2d, elle tourne dans un mouchoir de poche avec très peu d'effort aux commandes. Inversion de virage hyper facile, une grande joueuse. Par contre en haut de fourchette comme je suis, le tau de chute est certainement un peu plus important que d'autres voiles, faudra se battre en petites conditions. Les oreilles sont parfaites, accélérés on est vite à -3, -4 m/s. Excellent. Par contre y'a que 2 suspentes sur chacun des élévateurs en A, B et C + une de stabilo sur C, du coup aux oreilles, ben y'a plus que 2 suspentes en A.... J'ai essayé 2 fernture asymétrique avec un élévateur complet, ça part vite et le contre est sensible à la commande, il faudra le travailler pour ne pas surpiloter le jour venu. En fait j'ai pris une belle grosse fermeture asymétrique lors de l'un des vols, j'ai été vraiment limite et rès près du sur pilotage. Mais bon, c'est une EN B, je suppose qu'ele le mérite. J'ai fait plusieurs approches d'attéro en basses vitesses, elle a l'air très tolérente, elle reprend vite de la vitesse en remontant les mains. Le prix a aussi été un facteur d'achat, 400 euros de moins que la Diamir2 en prix publique, ça compte.
A27: Ozone | B27: Delta 3 | C27: 2017 | D27: MS | E27: =CONCATENATE(A27, " - ",B27," - ",D27) -> Ozone - Delta 3 - MS | F27: 75 / 95 | G27: C | H27: 23.1 | I27: =Matériel!$G$14/H27 -> #VALUE! | J27: 19.6 | K27: =Matériel!$G$14/J27 -> #VALUE! | L27: =(H27-J27)/H27*100 -> 15.151515 | M27: 6 | N27: 4.4 | O27: 5.3 | P27: 66 | Q27: 2+1 / 3 / 4 | R27: 7.27
A28: Gradient | B28: Aspen 6 | C28: 2017 | D28: 24 | E28: =CONCATENATE(A28, " - ",B28," - ",D28) -> Gradient - Aspen 6 - 24 | F28: 70-90 | G28: C | H28: 22.73 | I28: =Matériel!$G$14/H28 -> #VALUE! | J28: 18.93 | K28: =Matériel!$G$14/J28 -> #VALUE! | L28: =(H28-J28)/H28*100 -> 16.717994 | M28: 6.46 | N28: 4.99 | O28: 4.5 | P28: 66 | Q28: 3 / 3 / 4 | R28: 7 | S28: 244 | T28: 3950
A29: Sky Paragliders | B29: Exos | C29: 2017 | D29: M | E29: =CONCATENATE(A29, " - ",B29," - ",D29) -> Sky Paragliders - Exos - M | F29: 70 / 95 | G29: C | H29: 22.12 | I29: =Matériel!$G$14/H29 -> #VALUE! | J29: 19.42 | K29: =Matériel!$G$14/J29 -> #VALUE! | L29: =(H29-J29)/H29*100 -> 12.206148 | M29: 6.4 | N29: 4.92 | O29: 4 | P29: 65 | Q29: 2+1 / 3 / 2 / 2 | R29: 7.68 | S29: NC | T29: 4150
A30: Advance | B30: Sigma 11 | C30: 2021 | D30: 24 | E30: =CONCATENATE(A30, " - ",B30," - ",D30) -> Advance - Sigma 11 - 24 | F30: 85 / 97 | G30: C | H30: 23.6 | J30: 20.1 | L30: =(H30-J30)/H30*100 -> 14.830508 | M30: 6.07 | N30: 4.48 | O30: 4.5 | P30: 67 | Q30: 3/4/3

Sheet Matériel
A1: Marque | B1: Modèle | C1: Année | D1: Taille | E1: Historique | F1: Contrôle | G1: PTV | H1: Class. | I1: Surface à plat | J1: CH. Alaire à plat | K1: Surface projetée | L1: CH. Alaire proj | M1: Allongement | N1: Allongement projeté | O1: Poids | P1: Nbre cellule | Q1: Nbre lignes | R1: Longueur cône | S1: Mettrage suspente | T1: prix | U1: Rmqs | V1: Essai
A3: Swing | B3: Astral (1999-50h) | C3: 1998 | D3: M | G3: 75/100 | H3: DHV 2 | I3: 29.2 | M3: 5.15 | O3: 6.2 | P3: 54 | Q3: 2 + 1 /4 / 3 / 2 | R3: 7.5 | T3: 3000
A4: Advance | B4: Epsilon 3 (2000-75h) | C4: 1999 | D4: 28 | G4: 90/107 | H4: DHV 1-2 | I4: 27.4 | M4: 4.8 | O4: 6.3 | P4: 37 | Q4: 3 / 4 / 3 / 2 | R4: 7.94 | T4: 2900
A5: Windtech | B5: Quarx (2001-2002 - 65h) | C5: 1999 | D5: 27 | G5: 85/105 | H5: DHV 2 | I5: 27.1 | M5: 5.41 | O5: 6.8 | P5: 67 | Q5: 3 / 3 / 4 / 2 | R5: 7.7 | T5: 3000
A6: Windtech | B6: Serak (2003 - 35h/an) | C6: 2001 | D6: M | G6: 85/105 | H6: DHV 1-2 | I6: 27.55 | M6: 5.05 | O6: 7.2 | P6: 54 | Q6: 3 / 3 / 3 / 3 | R6: 7.2
A7: Gradient | B7: Aspen 1 (2004-2010 - 30h/an) | C7: 2003 | D7: 26 | G7: 80/100 | H7: DHV 2 | I7: 26.34 | M7: 5.58 | O7: 5.5 | P7: 52 | Q7: 3 / 3 / 4 / 2 | R7: 7.38 | S7: 360 | T7: 3050
A8: Gradient | B8: Golden 4 (2015-2017 - 50h/an) | C8: 2013 | D8: 24 | E8: Volé 100 heures en 17 mois, acheté 1800 € + 150 € de contrôle, vendu 1200 €, ça fait 7,5 €/h. Vendu à Olivier HERAULT de St Lary. Il a fait un vol avec et a été enchanté. | G8: 75 / 90 | H8: B | I8: 24.4 | K8: 21 | M8: 5.3 | N8: 4.16 | O8: 4.9 | P8: 51 | Q8: 2 +1 / 4 / 3 | R8: 6.57 | S8: 241 | T8: 3340
A9: Gradient | B9: Névada 2 - 24 Light | C9: 2017 | D9: 24 | E9: Acheté neuve 3000€ en 07/2017 | F9: Révision déc 2018 après 140h. Quelques retouches de calage. Drisses inferieures de frein changées. Durée de vie, 72% restant. ----------------------------- Révision 30/06/2020 à 210h. Tout en TBE, Porosité >300s, Déplacement global du centre d'attache de 39mm. Recalage léger de quelques suspentes. Durée de vie restante 75% ou 300h. ---------------------- Révision chez Jean-Marc en janvier 2022, à 300 heures. RAS. Porosité > 300s Tissus impeccable, quelques retouches de calage. Par contre, le constructeur préconise le remplacement du suspentage au bout de 5 ans ou 350heures. A voir en fin de saisosn. Durée de vie restante 70% ----------------------- Révision chez Jean-Marc le 30/09/2023 à 340 h avec test rupture suspente. tout est ok, la voile est bonne pour encore longtemps | G9: 75/90 | H9: B | I9: 23.2 | J9: 3.8 | K9: 19.61 | L9: 4.5 | M9: 5.8 | N9: 4.14 | O9: 4 | P9: 56 | Q9: 2 / 3 / 2
A10: 777 | B10: Queen 2 | C10: 2018 | D10: MS | E10: Acheté 2400€ en fin d'année avec 10h de vol. Volé 13h avec, vendu suite gros vrac à 1900€ | F10: Révision 1 mai 2019 après 20 h de vol. Pour revente chez Ripair. | G10: 80/100 | H10: C | I10: 25.3 | J10: 3.75 | K10: 21.4 | L10: 4.44 | M10: 6.3 | N10: 4.6 | O10: 5.1 | P10: 73 | Q10: 2+1 / 4 / 3
A11: Gradient | B11: BI Golden 2 - 38 | C11: 2013 | D11: 38 | E11: Acheté à Fabien Pratviel qui avait fait une cinnquantaine de ploufs du matin avec. Chanagement des élélvateurs solo pour des bi neufs. | F11: Révision Déc 2018 après envrion 50 heures de vol. Jugée en très bon état, Reste plus de 80% de durée de vie.
A12: Supair | B12: Extralight | C12: 2016 | E12: Secours sellette Swing puis Supair Evolite | F12: Aéré, replié le 08/03/2020 Aéré, replié le 05/03/2023 | G12: Max 105
A13: Supair | B13: Montagne | C13: 2019 | E13: Secours avec conteneur ventral pour montagne | F13: Aéré, replié le 08/03/2020 Aéré et replié le 05/03/2023 | G13: Max 85
A14: Mcc Aviation | B14: Secours SOS Bi | C14: 2013 | D14: Max 200 kg | E14: N° Certification PS 037.0101 1354-32-05'11 Produit en avril 2013 Acheté à Thierry Struxiano Surfair en 2017. | F14: Aéré, replié le 03/05/2020 Lancé sous tyrolienne et replié le 15/03/2021 Aéré et replié le 05/03/2023. Les panneaux de fermeture du conteneur restaient adhérents au Pod. Réformé et remplacé par modèlme identique. | G14: 135-180 Max 200
A15: Supair | B15: Walibi Lite biplace | C15: 2017 | D15: ML | E15: Acheté d'occasion 400€ début 2018. N° série 2167.ML.11.28Dtae fab 30;11;2017 | F15: Contrôle tous les 2 ans Ok le 03/05/2020 Ok le 15/03/2021 | G15: Max 120
A16: Supair | B16: VIP2 - Passager biplace | C16: 2020 | E16: Acheté neuve à Surfair à 515 € en 07/2020 | G16: Max 120
A17: Kortel | B17: Kruyer 3 | C17: 2020 | D17: M | E17: Achetée neuve à Surfair le14/08/2020 à 288€TTC N° série 19197-KR-M-29
A18: Supair | B18: Casque School | C18: 2020 | D18: 56-62 | E18: Acheté neuf à Surfair pour 76€ le 14/08/2020
A19: Supair | B19: Ecarteur rigide | C19: 2020 | E19: Achetés neuf à Surfair pour 80 €TTC le 14/08/2020
A20: BGD | B20: Dual 41 | C20: 2018 | E20: Acheté à Mumu en octobre 2020 avec environ 140 vols en très très bon état. Révision chez jean-Marc en jenvier 2022, état général excellent, sauf certaines couleurs de tissus qui sont un peu plus poreuses (rouge). Porosité > 300 sec. Durée restante 70%
A21: Advance | B21: Sigma 11 | C21: 2022 | D21: 24 | E21: Achetée neuve à Surfair en sept 2022, 4070 euros, un sacré joli cadeau ! | F21: 2022 21h de vol. 2023 112 h de vol Révision 30/09/2023 chez Jean-Marc. Tout ok, sauf une suspente abimée (par frottement ?) qu'il a changé. | G21: 80/100 | H21: En C | I21: 23.6 | J21: 3.8 | K21: 20.1 | L21: 4.48 | M21: 6.01 | N21: 4.48 | O21: 4.45 | P21: 65 | Q21: 3/3/2
A22: MCC Aviation | B22: SOS micro BI | C22: 2023 | D22: Bi | E22: Neuf acheté chez Surfair 932 € SN 2855-32-0659 | G22: Max 210 kg
A23: Supair | B23: Casque Pilot cosmos | C23: 2023 | E23: Acheté neuf chez Surfair 115 €
A24: Niviuk | B24: Ikuma 3 P | C24: 2024 | D24: 24 | E24: Achetée neuve chez Surfair 3534 € (-23%) | F24: Révision chez Vairiféo le 20/05/2025 après un peu plus de 200 h de vol. Tout va bien. Calage fin 2025 à 340h, stab rallongé sinon ok Retour Colombie début mars, elle a 434h | G24: 75/95 | H24: En B
A25: Kortel | B25: Kuik 3 | C25: 2024 | D25: M | E25: Achetée neuve chez Surfair 1550 € (-11%)

Sheet Synthèse
A1: Année | C1: Nbre de vols | D1: Nbre d'heures | E1: Durée moy / vol | F1: Distance en cross | G1: Nbre de cross | H1: Dist moy par cross | I1: Durée moy / an (15 ans)
B2: TOTAL | C2: =SUM(C3:C28) -> 1574 | D2: =SUM(D3:D28) -> 1628.9828 | E2: =C2/D2 -> 0.96624717 | F2: =SUM(F3:F267) -> 8160.38 | G2: =SUM(G3:G28) -> 230 | H2: =F2/G2 -> 35.479913 | I2: =D2/15 -> 108.59885
A3: 96-98 | B3: Stages | C3: =SUM('Vols 96 au 01_06_2000'!A2:A74) -> 67 | D3: =SUM('Vols 96 au 01_06_2000'!N2:N74)/60 -> 18.241667
A4: 99 | B4: Astral 1 | C4: =SUM('Vols 96 au 01_06_2000'!A75:A174) -> 90 | D4: =SUM('Vols 96 au 01_06_2000'!N60:N174)/60 -> 49.25 | E4: =D4/C4 -> 0.54722222 | F4: =SUM('Vols 96 au 01_06_2000'!P71:P174) -> 68
A5: 2000 | B5: Epsilon 3-28 | C5: =SUM('Vols 96 au 01_06_2000'!A175:A224)+SUM('2000'!A2:A57) -> 106 | D5: =(SUM('2000'!K:K)+SUM('Vols 96 au 01_06_2000'!N175:N224))/60 -> 77.35 | E5: =D5/C5 -> 0.72971698 | F5: =SUM('2000'!M:M)+SUM('Vols 96 au 01_06_2000'!P175:P224) -> 349.58 | G5: =COUNTA('2000'!M:M)-1 -> 12 | H5: =F5/G5 -> 29.131667
A6: 2001 | B6: Quarx 1-M | C6: =SUM('2001'!A:A) -> 95 | D6: =SUM('2001'!K:K)/60 -> 66.15 | E6: =D6/C6 -> 0.69631579 | F6: =SUM('2001'!M:M) -> 223 | G6: =COUNTA('2001'!M:M)-1 -> 11 | H6: =F6/G6 -> 20.272727
A7: 2002 | B7: Quarx puis Sérak M | C7: =SUM('2002'!A:A) -> 47 | D7: =SUM('2002'!K:K)/60 -> 36.25 | E7: =D7/C7 -> 0.7712766 | F7: =SUM('2002'!L:L) -> 188 | G7: =COUNTA('2002'!L:L)-1 -> 9 | H7: =F7/G7 -> 20.888889
A8: 2003 | B8: Sérak | C8: =SUM('2003'!A:A) -> 48 | D8: =SUM('2003'!K:K)/60 -> 37.8 | E8: =D8/C8 -> 0.7875 | F8: =SUM('2003'!L:L) -> 282.5 | G8: =COUNTA('2003'!L:L)-1 -> 9 | H8: =F8/G8 -> 31.388889
A9: 2004 | B9: Sérak puis Aspen 1-26 | C9: =SUM('2004'!A:A) -> 38 | D9: =SUM('2004'!K:K)/60 -> 34.683333 | E9: =D9/C9 -> 0.9127193 | F9: =SUM('2004'!L:L) -> 217 | G9: =COUNTA('2004'!L:L)-1 -> 7 | H9: =F9/G9 -> 31
A10: 2005 | B10: Aspen 26 | C10: =SUM('2005'!A:A) -> 45 | D10: =SUM('2005'!K:K)/60 -> 32.816667 | E10: =D10/C10 -> 0.72925926 | F10: =SUM('2005'!L:L) -> 209 | G10: =COUNTA('2005'!L:L)-1 -> 5 | H10: =F10/G10 -> 41.8
A11: 2006 | B11: Aspen , Golden puis Stream | C11: =SUM('2006'!A:A) -> 34 | D11: =SUM('2006'!K:K)/60 -> 32.32 | E11: =D11/C11 -> 0.95058824 | F11: =SUM('2006'!L:L) -> 104 | G11: =COUNTA('2006'!L:L)-1 -> 3 | H11: =F11/G11 -> 34.666667
A12: 2007 | B12: Stream 26 | C12: =SUM('2007'!A:A) -> 28 | D12: =SUM('2007'!K:K)/60 -> 25.179444 | E12: =D12/C12 -> 0.89926587 | F12: =SUM('2007'!L:L) -> 139.5 | G12: =COUNTA('2007'!L:L)-1 -> 8 | H12: =F12/G12 -> 17.4375
A13: 2008 | B13: Stream 26 | C13: =SUM('2008'!A:A) -> 23 | D13: =SUM('2008'!K:K)/60 -> 26.433333 | E13: =D13/C13 -> 1.1492754 | F13: =SUM('2008'!L:L) -> 129.5 | G13: =COUNTA('2008'!L:L)-1 -> 5 | H13: =F13/G13 -> 25.9
A14: 2009 | B14: Stream 26 | C14: =SUM('2009'!A:A) -> 15 | D14: ='2009'!K18 -> 24.05 | E14: =D14/C14 -> 1.6033333 | F14: =SUM('2009'!L:L) -> 22.9 | G14: =COUNTA('2009'!L:L)-1 -> 1 | H14: =F14/G14 -> 22.9
A15: 2010 | B15: Stream 26 | C15: 1 | D15: 2
A16: ='2015'!A2 -> 5 ans sont passés, j'ai fait 3 saisons de planeurs, mais trop d'éléments me repoussent du VV. Je décide de ré essayer le parapente, à Arbas avec Surfair (Thierry et Richard), retour en pente école, nouveau premier grand vol, je n'ai pas perdu le fond, comme en vélo parait il, on oublie pas les fondamentaux... de là à dire que je vais vraiment m'y remettre .... Inch'Allah.
A17: Année | C17: Nbre de vols | D17: Nbre d'heures | E17: Durée moy / vol | F17: Distance en cross | G17: Nbre de cross | H17: Dist moy par cross
A18: 2015 | B18: Golden 4 26-Location | C18: 20 | D18: 15.5 | E18: =D18/C18 -> 0.775 | I18: Reprise en grande sérénité sous la houlette de Thierry et Richard.
A19: 2016 | B19: Golden 4 24 | C19: =SUM('2016'!A:A) -> 58 | D19: =SUM('2016'!N:N)/60 -> 59.266667 | E19: =D19/C19 -> 1.0218391 | F19: =SUM('2016'!P:P) -> 176 | G19: =COUNTA('2016'!P:P)-1 -> 7 | H19: =F19/G19 -> 25.142857 | I19: Peu à peu je (re)trouve de bonnes sensations malgré des météos pas très favorables. Entre autre je n'ai jamais eu de vraiment bonnes condictions à Arbas pour partir en cross. J'ai su prendre mon temps, pour accumuler des heures et de l'entrainement. Les apports du livre de David Eyraud sont importants, il faut continuer dans ce sens. Les derniers cross de St Lary et Val Louron ont été magnifiques. J'espère pourvoir très vite retrouver de telles conditions.
A20: 2017 | B20: Golden 4 24 puis Névada 2 light | C20: =SUM('2017'!A:A) -> 87 | D20: =SUM('2017'!L:L)/60 -> 100.6 | E20: =D20/C20 -> 1.1563218 | F20: =SUM('2017'!N:N) -> 255 | G20: =COUNTA('2017'!N:N)-1 -> 10 | H20: =F20/G20 -> 25.5
A21: 2018 | B21: Névada 2 24 light | C21: =SUM('2018'!A:A) -> 140 | D21: =SUM('2018'!N:N)/60 -> 129.06667 | E21: =D21/C21 -> 0.92190476 | F21: =SUM('2018'!P:P) -> 517 | G21: =COUNTA('2018'!P:P)-1 -> 14 | H21: =F21/G21 -> 36.928571 | I21: Année géniale, déplacements dans les Alpes, Maroc, Espagne, 1 compet au revard… Superrrr
A22: 2019 | B22: Névada 2 24 light | C22: =SUM('2019'!A:A) -> 77 | D22: =SUM('2019'!N:N)/60 -> 85.066667 | E22: =D22/C22 -> 1.1047619 | F22: =SUM('2019'!P:P) -> 451 | G22: =COUNTA('2019'!P:P)-1 -> 10 | H22: =F22/G22 -> 45.1 | I22: Année horibilis, en espérant que 2020 soit plus clémente et agréable
A23: 2020 | B23: Névada 2 24 light | C23: =SUM('2020'!A:A) -> 52 | D23: =SUM('2020'!N:N)/60 -> 82.716667 | E23: =D23/C23 -> 1.5907051 | F23: =SUM('2020'!P:P) -> 138 | G23: =COUNTA('2020'!P:P)-1 -> 4 | H23: =F23/G23 -> 34.5 | I23: Année du début du Covid et de ses limitations et autres confinements… Bref pas la super année pour voler.
A24: 2021 | B24: Névada 2 24 light | C24: =SUM('2021'!A:A) -> 54 | D24: =SUM('2021'!N:N)/60 -> 55.483333 | E24: =D24/C24 -> 1.0274691 | F24: =SUM('2021'!P:P) -> 78 | G24: =COUNTA('2021'!P:P)-1 -> 3 | H24: =F24/G24 -> 26 | I24: Encore une année de transition, que des vols à Arbas, mais la vie change, maison à Mancioux, arrivée de Natalia et Miguel en avril puis de Réjane en octobre. Pas de voyage… une année pauvre pour le parapente, riche pour notre vie.
A25: 2022 | B25: Névada 2 24 light | C25: =SUM('2022'!A:A) -> 55 | D25: =SUM('2022'!N:N)/60 -> 58.666667 | E25: =D25/C25 -> 1.0666667 | F25: =SUM('2022'!P:P) -> 181 | G25: =COUNTA('2022'!P:P)-1 -> 8 | H25: =F25/G25 -> 22.625 | I25: Beaucoup de travaux à la maison de Mancioux avec l'aménagement de l'appartement de Réjane. Je me suis bien rattrapé après l'été mais il a manqué de vols mémorables.
A26: 2023 | B26: Sigma 11 24 | C26: =SUM('2023'!A:A) -> 120 | D26: =SUM('2023'!N:N)/60 -> 153.83333 | E26: =D26/C26 -> 1.2819444 | F26: =SUM('2023'!P:P) -> 801.4 | G26: =COUNTA('2023'!P:P)-1 -> 24 | H26: =F26/G26 -> 33.391667 | I26: Enfin dégagé des travaux, j'étais fin près au début du printemps pour une grosse année …. Raté, météo pourri. Je décroche quand même un beau Arbas-Foix, un peu par hasard, 2 passage de la Garonne mais pas géniaux et par contre, le vol de l'année, 70 kms en triangle FAI au départ de Val Louron avec des plafs à plus de 4000. énooooorme. Le 7 décembre Réjane meurt, ça par contre c'est la grande douleur !
A27: 2024 | B27: Sigma 11 24 puis Ikuma 3P 3P 24 | C27: =SUM('2024'!A:A) -> 137 | D27: =SUM('2024'!N:N)/60 -> 162.70833 | E27: =D27/C27 -> 1.1876521 | F27: =SUM('2024'!P:P) -> 699 | G27: =COUNTA('2024'!P:P)-1 -> 18 | H27: =F27/G27 -> 38.833333 | I27: Un SIV avec Soaring en mai me montre une carence de retard de tempo sur les abatées. Je change donc de voile pour "sous traiter" ce défaut.
A28: 2025 | B28: Ikuma 3 P 24 | C28: =SUM('2025'!A:A) -> 137 | D28: =SUM('2025'!N:N)/60 -> 263.55 | E28: =D28/C28 -> 1.9237226 | F28: =SUM('2025'!P:P) -> 2931 | G28: =COUNTA('2025'!P:P)-1 -> 62 | H28: =F28/G28 -> 47.274194
A29: 2026 | B29: Ikuma 3 P 24

Sheet 2026
A1: Compt | B1: N° Vol | C1: Date | D1: Voile | E1: Région | F1: Déco | G1: Acc. | H1: Dén. | I1: Attéro | J1: Type de vol | K1: Météo | L1: A1 max | M1: Heure décollage (locale) | N1: Durée | O1: Durée cumulée | P1: Dist | Q1: Rmq
A2: 29 | B2: =1562+29 -> 1591 | C2: Janv. Fevr. | D2: Ikuma 3P - 24 | E2: Colombie | N2: =(94*60)+50 -> 5690 | O2: =N2/60 -> 94.833333 | P2: 1650
A3: 1 | B3: 1592 | C3: 46090 | D3: Ikuma 3P - 24 | E3: Pyrénées | F3: Planot | I3: Arbas | J3: Local | N3: 99 | O3: =O2+N3/60 -> 96.483333
A4: 1 | B4: 1593 | C4: 46094 | D4: Ikuma 3P - 24 | E4: Pyrénées | F4: Planot | I4: Aspect | J4: Cross | N4: 135 | O4: =O3+N4/60 -> 98.733333 | P4: 30
A5: 1 | B5: 1594 | C5: 46097 | D5: Ikuma 3P - 24 | E5: Pyrénées | F5: Planot | I5: Arbas | J5: Local | N5: 100 | O5: =O4+N5/60 -> 100.4
A6: 1 | B6: 1595 | C6: 46098 | D6: Ikuma 3P - 24 | E6: Pyrénées | F6: Planot | I6: Arbas | J6: Local | N6: 99 | O6: =O5+N6/60 -> 102.05
A7: 1 | B7: 1596 | C7: 46101 | D7: essai Alpina5 | E7: Pyrénées | F7: Planot | I7: Arbas | J7: Local | N7: 30 | O7: =O6+N7/60 -> 102.55
A8: 1 | B8: 1597 | C8: 46101 | D8: essai Alpina5 | E8: Pyrénées | F8: Planot | I8: Urau | J8: Local | N8: 82 | O8: =O7+N8/60 -> 103.91667
A9: 1 | B9: 1598 | C9: 46102 | D9: essai Alpina5 | E9: Pyrénées | F9: Planot | I9: Arbas | J9: Cross | N9: 240 | O9: =O8+N9/60 -> 107.91667 | P9: 50
A10: 1 | B10: 1599 | C10: 46104 | D10: Ikuma 3P - 24 | E10: Pyrénées | F10: Planot | I10: St Girons | J10: Cross | N10: 100 | O10: =O9+N10/60 -> 109.58333 | P10: 36
A11: 1 | B11: 1600 | C11: 46105 | D11: Ikuma 3P - 24 | E11: Pyrénées | F11: Planot | I11: Arbas | J11: Cross | N11: 188 | O11: =O10+N11/60 -> 112.71667 | P11: 31
A12: 1 | B12: 1601 | O12: =O11+N12/60 -> 112.71667

Sheet 2025
A1: Compt | B1: N° Vol | C1: Date | D1: Voile | E1: Région | F1: Déco | G1: Acc. | H1: Dén. | I1: Attéro | J1: Type de vol | K1: Météo | L1: A1 max | M1: Heure décollage (locale) | N1: Durée | O1: Durée cumulée | P1: Dist | Q1: Rmq
A2: 1 | B2: 1428 | C2: 45658 | D2: Ikuma 3P - 24 | E2: Pyrénées | F2: Cornudère | G2: Rando | H2: 400 | I2: Arbas | J2: Local | K2: Flux de sud, veille d'arrivée de perturb | L2: 3145 | M2: 0.54652778 | N2: 85 | O2: =N2/60 -> 1.4166667 | P2: 40
A3: 1 | B3: 1429 | C3: 45667 | D3: Ikuma 3P - 24 | E3: Colombie | F3: Piedechinche | J3: Cross | N3: 140 | O3: =O2+N3/60 -> 3.75 | P3: 27
A4: 1 | B4: 1430 | C4: 45668 | D4: Ikuma 3P - 24 | E4: Colombie | F4: Piedechinche | J4: Local | N4: 104 | O4: =O3+N4/60 -> 5.4833333
A5: 1 | B5: 1431 | C5: 45669 | D5: Ikuma 3P - 24 | E5: Colombie | F5: Piedechinche | J5: Cross | N5: 45 | O5: =O4+N5/60 -> 6.2333333 | P5: 56
A6: 1 | B6: 1432 | C6: 45670 | D6: Ikuma 3P - 24 | E6: Colombie | F6: Piedechinche | J6: Cross | N6: 198 | O6: =O5+N6/60 -> 9.5333333 | P6: 43
A7: 1 | B7: 1433 | C7: 45671 | D7: Ikuma 3P - 24 | E7: Colombie | F7: Piedechinche | J7: Cross | N7: 184 | O7: =O6+N7/60 -> 12.6 | P7: 98
A8: 1 | B8: 1434 | C8: 45672 | D8: Ikuma 3P - 24 | E8: Colombie | F8: Roldanillo | J8: Cross | N8: 310 | O8: =O7+N8/60 -> 17.766667 | P8: 85
A9: 1 | B9: 1435 | C9: 45673 | D9: Ikuma 3P - 24 | E9: Colombie | F9: Roldanillo | J9: Cross | N9: 287 | O9: =O8+N9/60 -> 22.55 | P9: 64
A10: 1 | B10: 1436 | C10: 45674 | D10: Ikuma 3P - 24 | E10: Colombie | F10: Roldanillo | J10: Cross | N10: 198 | O10: =O9+N10/60 -> 25.85 | P10: 114
A11: 1 | B11: 1437 | C11: 45675 | D11: Ikuma 3P - 24 | E11: Colombie | F11: Roldanillo | J11: Cross | N11: 348 | O11: =O10+N11/60 -> 31.65 | P11: 55
A12: 1 | B12: 1438 | C12: 45676 | D12: Ikuma 3P - 24 | E12: Colombie | F12: Roldanillo | J12: Cross | N12: 198 | O12: =O11+N12/60 -> 34.95 | P12: 65
A13: 1 | B13: 1439 | C13: 45677 | D13: Ikuma 3P - 24 | E13: Colombie | F13: Ansermanuevo | J13: Cross | N13: 266 | O13: =O12+N13/60 -> 39.383333 | P13: 50
A14: 1 | B14: 1440 | C14: 45678 | D14: Ikuma 3P - 24 | E14: Colombie | F14: Ansermanuevo | J14: Cross | N14: 175 | O14: =O13+N14/60 -> 42.3 | P14: 83
A15: 1 | B15: 1441 | C15: 45679 | D15: Ikuma 3P - 24 | E15: Colombie | F15: Ansermanuevo | J15: Local | N15: 305 | O15: =O14+N15/60 -> 47.383333
A16: 1 | B16: 1442 | C16: 45681 | D16: Ikuma 3P - 24 | E16: Colombie | F16: Piedechinche | J16: Local | N16: 109 | O16: =O15+N16/60 -> 49.2
A17: 1 | B17: 1443 | C17: 45682 | D17: Ikuma 3P - 24 | E17: Colombie | F17: Piedechinche | J17: Local | N17: 163 | O17: =O16+N17/60 -> 51.916667
A18: 1 | B18: 1444 | C18: 45683 | D18: Ikuma 3P - 24 | E18: Colombie | F18: Piedechinche | J18: Cross | N18: 50 | O18: =O17+N18/60 -> 52.75 | P18: 11
A19: 1 | B19: 1445 | C19: 45684 | D19: Ikuma 3P - 24 | E19: Colombie | F19: Roldanillo | J19: Cross | N19: 184 | O19: =O18+N19/60 -> 55.816667 | P19: 59
A20: 1 | B20: 1446 | C20: 45685 | D20: Ikuma 3P - 24 | E20: Colombie | F20: Ansermanuevo | J20: Cross | N20: 228 | O20: =O19+N20/60 -> 59.616667 | P20: 73
A21: 1 | B21: 1447 | C21: 45687 | D21: Ikuma 3P - 24 | E21: Colombie | F21: Jerico | J21: Cross | N21: 118 | O21: =O20+N21/60 -> 61.583333 | P21: 24
A22: 1 | B22: 1448 | C22: 45694 | D22: Ikuma 3P - 24 | E22: Colombie | F22: Ansermanuevo | J22: Cross | N22: 182 | O22: =O21+N22/60 -> 64.616667 | P22: 57
A23: 1 | B23: 1449 | C23: 45695 | D23: Ikuma 3P - 24 | E23: Colombie | F23: Ansermanuevo | J23: Cross | N23: 253 | O23: =O22+N23/60 -> 68.833333 | P23: 73
A24: 1 | B24: 1450 | C24: 45696 | D24: Ikuma 3P - 24 | E24: Colombie | F24: Ansermanuevo | J24: Cross | N24: 112 | O24: =O23+N24/60 -> 70.7 | P24: 30
A25: 1 | B25: 1451 | C25: 45697 | D25: Ikuma 3P - 24 | E25: Colombie | F25: Ansermanuevo | J25: Cross | N25: 127 | O25: =O24+N25/60 -> 72.816667 | P25: 30
A26: 1 | B26: 1452 | C26: 45698 | D26: Ikuma 3P - 24 | E26: Colombie | F26: Ansermanuevo | J26: Cross | N26: 211 | O26: =O25+N26/60 -> 76.333333 | P26: 58
A27: 1 | B27: 1453 | C27: 45700 | D27: Ikuma 3P - 24 | E27: Colombie | F27: Ansermanuevo | J27: Cross | N27: 265 | O27: =O26+N27/60 -> 80.75 | P27: 71
A28: 1 | B28: 1454 | C28: 45708 | D28: Ikuma 3P - 24 | E28: Pyrénées | F28: Planot | G28: Navette | I28: Arbas | J28: Cross | L28: 2700 | M28: 0.51388889 | N28: 115 | O28: =O27+N28/60 -> 82.666667 | P28: 32
A29: 1 | B29: 1455 | C29: 45711 | D29: Ikuma 3P - 24 | E29: Pyrénées | F29: Cornudère | G29: Rando | H29: 400 | I29: Arbas | J29: Cross | L29: 1800 | M29: 0.52777778 | N29: 178 | O29: =O28+N29/60 -> 85.633333 | P29: 35
A30: 1 | B30: 1456 | C30: 45716 | D30: Ikuma 3P - 24 | E30: Pyrénées | F30: Planot | G30: Navette | I30: Sengouagnet | J30: Cross | L30: 1700 | M30: 0.50416667 | N30: 51 | O30: =O29+N30/60 -> 86.483333 | P30: 10
A31: 1 | B31: 1457 | C31: 45717 | D31: Ikuma 3P - 24 | E31: Pyrénées | F31: Planot | G31: Navette | I31: Arbas | J31: Local | N31: 21 | O31: =O30+N31/60 -> 86.833333 | Q31: Essai sellette Advance ligtness4 de Jeanseb. Pas assez amorti, trop coucvhé
A32: 1 | B32: 1458 | C32: 45717 | D32: Ikuma 3P - 24 | E32: Pyrénées | F32: Cier de Rivière | G32: Rando | H32: 250 | I32: Cier de rivière | J32: Local | N32: 65 | O32: =O31+N32/60 -> 87.916667
A33: 1 | B33: 1459 | C33: 45719 | D33: Ikuma 3P - 24 | E33: Pyrénées | F33: Planot | G33: Rando | H33: 500 | I33: Arbas | J33: Local | N33: 21 | O33: =O32+N33/60 -> 88.266667
A34: 1 | B34: 1460 | C34: 45720 | D34: Ikuma 3P - 24 | E34: Pyrénées | F34: Planot | G34: Navette | I34: Arbas | J34: Local | N34: 123 | O34: =O33+N34/60 -> 90.316667
A35: 1 | B35: 1461 | C35: 45721 | D35: Ikuma 3P - 24 | E35: Pyrénées | F35: Planot | G35: Navette | I35: Arbas | J35: Local | M35: 0.47777778 | N35: 180 | O35: =O34+N35/60 -> 93.316667
A36: 1 | B36: 1462 | C36: 45734 | D36: Ikuma 3P - 24 | E36: Pyrénées | F36: Planot | G36: Navette | I36: Bize | J36: Cross | L36: 1644 | M36: 0.51527778 | N36: 99 | O36: =O35+N36/60 -> 94.966667 | P36: 36
A37: 1 | B37: 1463 | C37: 45746 | D37: Ikuma 3P - 24 | E37: Pyrénées | F37: Planot | J37: Local | N37: 97 | O37: =O36+N37/60 -> 96.583333
A38: 1 | B38: 1464 | C38: 45747 | D38: Ikuma 3P - 24 | E38: Pyrénées | F38: Planot | J38: Local | N38: 50 | O38: =O37+N38/60 -> 97.416667
A39: 1 | B39: 1465 | C39: 45752 | D39: Ikuma 3P - 24 | E39: Pyrénées | F39: Cier de Rivière | G39: Rando | H39: 200 | J39: Local | N39: 40 | O39: =O38+N39/60 -> 98.083333
A40: 1 | B40: 1466 | C40: 45753 | D40: Ikuma 3P - 24 | E40: Pyrénées | F40: Cier de Rivière | G40: Rando | H40: 250 | J40: Local | N40: 52 | O40: =O39+N40/60 -> 98.95
...

Sheet 2024
A1: Compt | B1: N° Vol | C1: Date | D1: Voile | E1: Région | F1: Déco | G1: Acc. | H1: Dén. | I1: Attéro | J1: Type de vol | K1: Météo | L1: A1 max | M1: Heure décollage (locale) | N1: Durée | O1: Durée cumulée | P1: Dist | Q1: Rmq
A2: 1 | B2: 1292 | C2: 45295 | D2: Névada 2 -24 | E2: Pyrénées | F2: Planot | G2: Rando | H2: 700 | I2: Arbas | J2: Local | K2: Léger flux d'Ouest | M2: 0.54305556 | N2: 25 | O2: =25/60 -> 0.41666667
A3: 1 | B3: 1293 | C3: 45296 | D3: Névada 2 -24 | E3: Pyrénées | F3: Cornudère | G3: Rando | H3: 400 | I3: Arbas | J3: Cross | L3: 1825 | M3: 0.53472222 | N3: 118 | O3: =O2+N3/60 -> 2.3833333 | P3: 24
A4: 1 | C4: 45306 | D4: Névada 2 -24 | E4: Mancioux | O4: =O3+N4/60 -> 2.3833333 | Q4: Gonflage à Paris les Près 1h envron
A5: 1 | B5: 1294 | C5: 45301 | D5: Névada 2 -24 | E5: Pyrénées | F5: Roquefort / Garonne | H5: 220 | I5: Roquefort / Garonne | J5: Local | M5: 0.675 | N5: 4 | O5: =O4+N5/60 -> 2.45
A6: 1 | B6: 1295 | C6: 45304 | D6: Sigma 11-24 | E6: Pyrénées | F6: Le relais | G6: Navette | I6: Arbas | J6: Local | M6: 0.54513889 | N6: 6 | O6: =O5+N6/60 -> 2.55
A7: 1 | B7: 1296 | C7: 45304 | D7: Sigma 11-24 | E7: Pyrénées | F7: Planot | G7: Rando | H7: 700 | I7: Arbas | J7: Local | M7: 0.58263889 | N7: 15 | O7: =O6+N7/60 -> 2.8
A8: 1 | B8: 1297 | C8: 45312 | D8: Sigma 11-24 | E8: Pyrénées | F8: Cornudère | G8: Rando | H8: 400 | I8: Arbas | J8: Cross | K8: Léger SO | L8: 1785 | M8: 0.56458333 | N8: 120 | O8: =O7+N8/60 -> 4.8 | P8: 20 | Q8: Le vol est super chouette, mais …. Aujourd'hui j'ai merdé. Déco sud de Cornudere, je me fais arracher, un peu traîner au sol, la voile fini dans la keke. C'était craignos, absolument pas maîtrisé, je sais à peu près pourquoi, mais ... passons. Je mets la voile en boule, je vais au deco Sud Ouest, grand Mitch et Jean Marc m'aident à remettre de l'ordre, ils me demandent si j'ai debouclé les cuissardes et ventral, Ras, je gonfle, je décolle, je vole 2h avec grand plaisir et, à l'atterro, je constate que j'aurai très bien pu faire secours en automatique, une des aiguilles de la poignée est défaite. Voir photo. La prochaine fois que ça m'arrive, je reprends tout à zéro, prévol et tout le reste !
A9: 1 | B9: 1298 | C9: 45315 | D9: Névada 2 -24 | E9: Pyrénées | F9: Cornudère | G9: Rando | H9: 400 | I9: Arbas | J9: Local | L9: 1550 | M9: 0.58611111 | N9: 54 | O9: =O8+N9/60 -> 5.7
A10: 1 | B10: 1299 | C10: 45318 | D10: Sigma 11-24 | E10: Pyrénées | F10: Superbagnères | G10: Télécabine | I10: Luchon | J10: Local | M10: 0.45694444 | N10: 16 | O10: =O9+N10/60 -> 5.9666667
A11: 1 | B11: 1300 | C11: 45318 | D11: Sigma 11-24 | E11: Pyrénées | F11: Superbagnères | G11: Télécabine | I11: Luchon | J11: Local | M11: 0.51041667 | N11: 18 | O11: =O10+N11/60 -> 6.2666667
A12: 1 | B12: 1301 | C12: 45318 | D12: Sigma 11-24 | E12: Pyrénées | F12: Superbagnères | G12: Télécabine | I12: Luchon | J12: Local | M12: 0.55902778 | N12: 20 | O12: =O11+N12/60 -> 6.6
A13: 1 | B13: 1302 | C13: 45319 | D13: Névada 2 -24 | E13: Pyrénées | F13: Cornudère | G13: Rando | H13: 400 | I13: Bas de cornu sud | J13: Local | L13: 1800 | M13: 0.53958333 | N13: 51 | O13: =O12+N13/60 -> 7.45
A14: 1 | B14: 1303 | C14: 45319 | D14: Névada 2 -24 | E14: Pyrénées | F14: Michel Bellaygues | G14: Rando | H14: 350 | I14: Arbas | J14: Local | M14: 0.62916667 | N14: 10 | O14: =O13+N14/60 -> 7.6166667
A15: 1 | B15: 1304 | C15: 45336 | D15: Sigma 11-24 | E15: Pyrénées | F15: Cornudère | G15: Rando | H15: 400 | I15: Arbas | J15: Cross | L15: 1750 | M15: 0.525 | N15: 98 | O15: =O14+N15/60 -> 9.25 | P15: 24 | Q15: Des bonnes sensations dans de bons thermiques, m'anènent jusqu'à l'ouest de Paloumère, puis par les faces sud jusqu'à Herbzq blanches, puis relais et attéro. J'aurai peut-être du patienter à la BA110, plus tard, certains on pu en sortir pour aller à l'Estelas. Mais pas grave, vol parfait !
A16: 1 | B16: 1305 | C16: 45343 | D16: Sigma 11-24 | E16: Pyrénées | F16: Planot | G16: Rando | H16: 700 | I16: Arbas | M16: 0.51666667 | N16: 66 | O16: =O15+N16/60 -> 10.35 | Q16: Essai de la sellette de Vincent Daoulas, une Supair Strike 2. pour une fois j'ai réussi à rentrer dedans assez facilement. Probablement pas très bien régler, mais le problème c'est surtout le manque d'amorti qui je suppose est du à la faible hauteur plateau/maillons. D'ailleurs s'en est génant pour la hauteur des mains pour les commandes. Je me retrouve à piloter mains très basses, coudes très pliés, et donc fatigant. Je la rend à Vincent sans regret ni envie d'achat.
A17: 1 | B17: 1306 | C17: 45351 | D17: Sigma 11-24 | E17: Pyrénées | F17: Planot | G17: Navette | I17: Arbas | J17: Cross | L17: 1700 | M17: 0.52777778 | N17: 113 | O17: =O16+N17/60 -> 12.233333 | Q17: Belles conditions d'hiver, bien tonique avec un mélange de couche de vent pas toujours agréable. Mais au gloabl un très bon vol.
A18: 1 | B18: 1307 | C18: 45357 | D18: Sigma 11-24 | E18: Pyrénées | F18: Planot | G18: Navette | I18: Arbas | J18: Cross | L18: 1575 | M18: 0.50347222 | N18: 135 | O18: =O17+N18/60 -> 14.483333
A19: 1 | B19: 1308 | C19: 45358 | D19: Sigma 11-24 | E19: Pyrénées | F19: Planot | G19: Navette | I19: Arbas | J19: Local | L19: 1400 | M19: 0.5375 | N19: 129 | O19: =O18+N19/60 -> 16.633333 | Q19: Il ne fallait pas plus de vent ! Retour d'Est, Su fort en altitude, 20/40 à Cornu 70 au Pic du Midi.
A20: 1 | B20: 1309 | C20: 45363 | D20: Sigma 11-24 | E20: Pyrénées | F20: Cier de Rivière | G20: Rando | H20: 250 | I20: Cier de Rivière | J20: Local | M20: 0.65972222 | N20: 5.5 | O20: =O19+N20/60 -> 16.725 | Q20: Un plouf de Cier après être passé pour rien à Soueich, On en rit encore !
A21: 1 | B21: 1310 | C21: 45364 | D21: Sigma 11-24 | E21: Pyrénées | F21: Planot | G21: Rando | H21: 700 | I21: Arbas | J21: Local | M21: 0.51944444 | N21: 35 | O21: =O20+N21/60 -> 17.308333 | Q21: Très énervé par Olivier Grimoux que j'insulte parcequ'il me dérange 2 fois de suite après avoir déranger Thierry D. sans jamais changé d'attitude. Du coup j'ai pété un cable et je l'ai insulté. | R21: yer d
A22: 1 | B22: 1311 | C22: 45365 | D22: Sigma 11-24 | E22: Pyrénées | F22: Planot | G22: Rando | H22: 700 | I22: Aspect | J22: Cross | L22: 2025 | M22: 0.51736111 | N22: 88 | O22: =O21+N22/60 -> 18.775 | Q22: Parti pour faire un plouf sous un voile épais de cirrus, en afit ça sortait tout seul. Passage à Paloumère pour le challenge, retour difficile à la Husse et comme un con, j'essaie d'(aller tourner Caoubech et je me fait enterrer au retour face au NE trop fort pour moi. Je ressort par miracle sur les coteaux du coté de chez Luis et j'échoue à l'entrée d'Aspect. Je retrouve ma sellette après les 2 vols précédents avec la Delight 3. C'est pas fait pour moi !
A23: 1 | B23: 1312 | C23: 45366 | D23: Sigma 11-24 | E23: Pyrénées | F23: Planot | G23: Rando | H23: 700 | I23: Arbas | J23: Cross | L23: 2023 | M23: 0.49513889 | N23: 112 | O23: =O22+N23/60 -> 20.641667 | Q23: La journée était annoncé mauvaise, elle fut excellente. On se retrouve 4 au déco. E iront à la vallée de la Barousse, Thierry Strux, fait demi tout au Col des Ares, repasse à Arbas et finit apès St Girons. Mois, je fais les 2 1eres balises de mon triangle, mais j'échoue vers le relais sans plus rien trouver.
A24: 1 | B24: 1313 | C24: 45367 | D24: Sigma 11-24 | E24: Pyrénées | F24: Planot | G24: Navette | I24: Ural | J24: Compete | L24: 1508 | M24: 0.51944444 | N24: 118 | O24: =O23+N24/60 -> 22.608333 | P24: 25 | Q24: 1e manche de la compete d'Arbas, bon début de parcours, mais je merder du coté du relais ou je n'assure pas la plaf et je rate le retour de la pente école.*
A25: 1 | B25: 1314 | C25: 45368 | D25: Sigma 11-24 | E25: Pyrénées | F25: Planot | G25: Navette | I25: Arbas | J25: Compete | L25: 1889 | M25: 0.51180556 | N25: 203 | O25: =O24+N25/60 -> 25.991667 | P25: 40 | Q25: 2ieme manche. Cettef ois je boucle, c'est bien satisfaisant, mais je fais quasiment la même erreur que la veille, pour aller fire la dernière balise de Castelbiague, il aurait fallu fair le plaf au Mountagnat et taper un A/R express. Seule excuse, c'est le moment o^est rentré un voile épais. D'ailleurs de retour de Castelbiague, le soleil revenu, je suis ressorti de la pointe du massif derrière le relais avec facilité.
A26: 1 | B26: 1315 | C26: 45381 | D26: Sigma 11-24 | E26: Pyrénées | F26: Planot | G26: Navette | I26: Arbas | L26: 1543 | M26: 0.56041667 | N26: 109 | O26: =O25+N26/60 -> 27.808333
A27: 1 | B27: 1316 | C27: 45383 | D27: Sigma 11-24 | E27: Pyrénées | F27: Planot | G27: Navette | I27: Arbas | M27: 0.48333333 | N27: 36 | O27: =O26+N27/60 -> 28.408333
A28: 1 | B28: 1317 | C28: 45383 | D28: Sigma 11-24 | E28: Pyrénées | F28: Planot | G28: Navette | I28: Pt de Prades | J28: Cross | L28: 2600 | M28: 0.53333333 | N28: 113 | O28: =O27+N28/60 -> 30.291667 | P28: 27 | Q28: Flux d'ouest trop fort, limite pas volable. Sauf sous 1500 où c'était plus calme.*
A29: 1 | B29: 1318 | C29: 45385 | D29: Sigma 11-24 | E29: Pyrénées | F29: Planot | G29: Navette | I29: St Girons | J29: Cross | L29: 2074 | M29: 0.51041667 | N29: 136 | O29: =O28+N29/60 -> 32.558333 | P29: 37 | Q29: un peu pareil qe le vol précédent, trop d'ouest … NO mais cette fois volable. Après un bon plaf à l'Estelas, je tente de traverser la vallée su Salat par l'ouest de St Girons, mais je suis trop contré. Du coup je me retrouve entre Moulis et St Girons à l'endroit habituel ou ça monte, mais c'est trop NO et je ne veux pas partir dans le relief. Du coup, posé sécure à l'Est de St Girons.
A30: 1 | B30: 1319 | C30: 45386 | D30: Sigma 11-24 | E30: Pyrénées | F30: Planot | G30: Navette | I30: Cornudère | J30: Local | M30: 0.51041667 | N30: 30 | O30: =O29+N30/60 -> 33.058333
A31: 1 | B31: 1320 | C31: 45386 | D31: Sigma 11-24 | E31: Pyrénées | F31: Cornudère | I31: Arbas | J31: Cross | L31: 2125 | M31: 13 | N31: 199 | O31: =O30+N31/60 -> 36.375 | P31: 45
A32: 1 | B32: 1321 | C32: 45387 | D32: Sigma 11-24 | E32: Pyrénées | F32: Planot | G32: Navette | I32: Arbas | J32: Local | L32: 1485 | N32: 68 | O32: =O31+N32/60 -> 37.508333
A33: 1 | B33: 1322 | C33: 45393 | D33: Sigma 11-24 | E33: Pyrénées | F33: Planot | G33: Navette | I33: Arbas | J33: Cross | L33: 2125 | M33: 0.51805556 | N33: 252 | O33: =O32+N33/60 -> 41.708333 | P33: 46 | Q33: Pic du Gar, Herbes Blanches, Le relais. Beaucoup plus facil que la précédent car peu de vent.
A34: 1 | B34: 1323 | C34: 45394 | D34: Sigma 11-24 | E34: Pyrénées | F34: Val Louron 700 | G34: Navette | I34: Campan | J34: Cross | L34: 2878 | M34: 0.51736111 | N34: 166 | O34: =O33+N34/60 -> 44.475 | P34: 38 | Q34: Ca me renvoie 20 ans en arrière quand avec Jo et Réjane en CC, j'étais allé d'Arbas à Aregels Gasost en 3 vols. 2ième passage à l'Arbizon en 25 ans de parapente, c'est peu, mais c'est mon everest à moi. Par con,tre s'il y a une prochaine fois, il faudra que j'évite les ZSM.
